Workbook

Sheet standardized
A4: Powered by Clearbit
A5: Walmart Inc (NYS: WMT)
E6: =(E15/D15)-1 -> 0.030009329 | F6: =(F15/E15)-1 -> 0.029385127 | G6: =(G15/F15)-1 -> 0.018805516 | H6: =(H15/G15)-1 -> 0.067907741 | I6: =(I15/H15)-1 -> 0.022565301 | J6: =(J15/I15)-1 -> 0.067139048 | K6: =(K15/J15)-1 -> 0.060665378 | L6: =AVERAGE(E6:K6) -> 0.04235392
A7: Exchange rate used is that of the Year End reported date | E7: =(E16/D16)-1 -> 0.0057067603 | F7: =(F16/E16)-1 -> -0.11043213 | G7: =(G16/F16)-1 -> -0.0093228656 | H7: =(H16/G16)-1 -> -0.029717682 | I7: =(I16/H16)-1 -> 0.27411945 | J7: =(J16/I16)-1 -> 0.083333333 | K7: =(K16/J16)-1 -> 0.014792899 | L7: =AVERAGE(E7:K7) -> 0.032639967
A9: Revenue growth | C9: =C17/B17-1 -> -0.0072500623 | D9: =D17/C17-1 -> 0.0077634663 | E9: =E17/D17-1 -> 0.029781445 | F9: =F17/E17-1 -> 0.02810472 | G9: =G17/F17-1 -> 0.018582634 | H9: =H17/G17-1 -> 0.067155377 | I9: =I17/H17-1 -> 0.024327954 | J9: =J17/I17-1 -> 0.067280194 | K9: =K17/J17-1 -> 0.06025955 | L9: =AVERAGE(C9:K9) -> 0.032889475
A12: Standardized Annual Income Statement
A13: Report Date | B13: 01/31/2015 | C13: 01/31/2016 | D13: 01/31/2017 | E13: 01/31/2018 | F13: 01/31/2019 | G13: 01/31/2020 | H13: 01/31/2021 | I13: 01/31/2022 | J13: 01/31/2023 | K13: 01/31/2024 | L13: 2025 | M13: =L13+1 -> 2026 | N13: =M13+1 -> 2027 | O13: =N13+1 -> 2028 | P13: =O13+1 -> 2029 | Q13: =P13+1 -> 2030 | R13: =Q13+1 -> 2031
A15: Sales Revenue | B15: 482229000 | C15: 478614000 | D15: 481317000 | E15: 495761000 | F15: 510329000 | G15: 519926000 | H15: 555233000 | I15: 567762000 | J15: 605881000 | K15: 642637000
A16: Other Revenue | B16: 3422000 | C16: 3516000 | D16: 4556000 | E16: 4582000 | F16: 4076000 | G16: 4038000 | H16: 3918000 | I16: 4992000 | J16: 5408000 | K16: 5488000
A17: Total Revenue | B17: 485651000 | C17: 482130000 | D17: 485873000 | E17: 500343000 | F17: 514405000 | G17: 523964000 | H17: 559151000 | I17: 572754000 | J17: 611289000 | K17: 648125000 | L17: ='projected IS '!E22 -> 6.5166464e+08 | M17: ='projected IS '!F22 -> 6.744729e+08 | N17: ='projected IS '!G22 -> 7.0145182e+08 | O17: ='projected IS '!H22 -> 7.2950989e+08 | P17: ='projected IS '!I22 -> 7.6233783e+08 | Q17: ='projected IS '!J22 -> 7.9664304e+08 | R17: ='projected IS '!K22 -> 8.2850876e+08
A18: Direct Costs | B18: 365086000 | C18: 360984000 | D18: 361256000 | E18: 373396000 | F18: 385301000 | G18: 394605000 | H18: 420315000 | I18: 429000000 | J18: 463721000 | K18: 490142000
A19: Gross Profit | B19: 120565000 | C19: 121146000 | D19: 124617000 | E19: 126947000 | F19: 129104000 | G19: 129359000 | H19: 138836000 | I19: 143754000 | J19: 147568000 | K19: 157983000 | L19: ='projected IS '!E24 -> 1.6291616e+08 | M19: ='projected IS '!F24 -> 1.6861823e+08 | N19: ='projected IS '!G24 -> 1.6834844e+08 | O19: ='projected IS '!H24 -> 1.8967257e+08 | P19: ='projected IS '!I24 -> 2.0583122e+08 | Q19: ='projected IS '!J24 -> 2.2306005e+08 | R19: ='projected IS '!K24 -> 2.4855263e+08
A20: Selling General & Admin | B20: 93418000 | C20: 97041000 | D20: 101853000 | E20: 106510000 | F20: 107147000 | G20: 108791000 | H20: 116288000 | I20: 117812000 | J20: 127140000 | K20: 130971000
A21: Total Indirect Operating Costs | B21: 93418000 | C21: 97041000 | D21: 101853000 | E21: 106510000 | F21: 107147000 | G21: 108791000 | H21: 116288000 | I21: 117812000 | J21: 127140000 | K21: 130971000
A22: Operating Income | B22: 27147000 | C22: 24105000 | D22: 22764000 | E22: 20437000 | F22: 21957000 | G22: 20568000 | H22: 22548000 | I22: 25942000 | J22: 20428000 | K22: 27012000
A23: Interest Income | B23: -2348000 | C23: -2467000 | D23: -2267000 | E23: -2178000 | F23: -2129000 | G23: -2410000 | H23: -2194000 | I23: -1836000 | J23: -1874000 | K23: -2137000
A24: Other Non-Operating Income | B24: 0 | C24: 0 | D24: 0 | E24: -3136000 | F24: -8368000 | G24: 1958000 | H24: 210000 | I24: -5410000 | J24: -1538000 | K24: -3027000
A25: Total Non-Operating Income | B25: -2348000 | C25: -2467000 | D25: -2267000 | E25: -5314000 | F25: -10497000 | G25: -452000 | H25: -1984000 | I25: -7246000 | J25: -3412000 | K25: -5164000
A26: Earnings Before Tax | B26: 24799000 | C26: 21638000 | D26: 20497000 | E26: 15123000 | F26: 11460000 | G26: 20116000 | H26: 20564000 | I26: 18696000 | J26: 17016000 | K26: 21848000
A27: Taxation | B27: 7985000 | C27: 6558000 | D27: 6204000 | E27: 4600000 | F27: 4281000 | G27: 4915000 | H27: 6858000 | I27: 4756000 | J27: 5724000 | K27: 5578000
A28: Minority Interests | B28: 736000 | C28: 386000 | D28: 650000 | E28: 661000 | F28: 509000 | G28: 320000 | H28: 196000 | I28: 267000 | J28: -388000 | K28: 759000
A29: Net Income | B29: 16363000 | C29: 14694000 | D29: 13643000 | E29: 9862000 | F29: 6670000 | G29: 14881000 | H29: 13510000 | I29: 13673000 | J29: 11680000 | K29: 15511000 | L29: ='projected IS '!E33 -> 15239711 | M29: ='projected IS '!F33 -> 15445045 | N29: ='projected IS '!G33 -> 11286684 | O29: ='projected IS '!H33 -> 22383078 | P29: ='projected IS '!I33 -> 30198632 | Q29: ='projected IS '!J33 -> 37038836 | R29: ='projected IS '!K33 -> 50846402
A32: Preference Dividends & Similar | B32: 0 | C32: 0 | D32: 0 | E32: 0 | F32: 0 | G32: 0 | H32: 0 | I32: 0 | J32: 0 | K32: 0
A33: Net Income to Common | B33: 16363000 | C33: 14694000 | D33: 13643000 | E33: 9862000 | F33: 6670000 | G33: 14881000 | H33: 13510000 | I33: 13673000 | J33: 11680000 | K33: 15511000
A34: Average Shares Basic | B34: 3230000 | C34: 3207000 | D34: 3101000 | E34: 2995000 | F34: 2929000 | G34: 2850000 | H34: 2831000 | I34: 2792000 | J34: 2724000 | K34: 8077000
A35: EPS Net Basic | B35: 5.07 | C35: 4.58 | D35: 4.4 | E35: 3.29 | F35: 2.28 | G35: 5.22 | H35: 4.77 | I35: 4.9 | J35: 4.29 | K35: 1.92
A36: EPS Continuing Basic | B36: 5.01 | C36: 4.58 | D36: 4.4 | E36: 3.29 | F36: 2.28 | G36: 5.22 | H36: 4.77 | I36: 4.9 | J36: 4.29 | K36: 1.92
A37: Average Shares Diluted | B37: 3243000 | C37: 3217000 | D37: 3112000 | E37: 3010000 | F37: 2945000 | G37: 2868000 | H37: 2847000 | I37: 2805000 | J37: 2734000 | K37: 8108000
A38: EPS Net Diluted | B38: 5.05 | C38: 4.57 | D38: 4.38 | E38: 3.28 | F38: 2.26 | G38: 5.19 | H38: 4.75 | I38: 4.87 | J38: 4.27 | K38: 1.91
A39: EPS Continuing Diluted | B39: 4.99 | C39: 4.57 | D39: 4.38 | E39: 3.28 | F39: 2.26 | G39: 5.19 | H39: 4.75 | I39: 4.87 | J39: 4.27 | K39: 1.91
A40: Shares Outstanding | B40: 3228000 | C40: 3162000 | D40: 3048000 | E40: 2952000 | F40: 2878000 | G40: 2832000 | H40: 2821000 | I40: 2761000 | J40: 2693000 | K40: 8054000
A47: Total Revenue | B47: 476294000 | C47: 485651000 | D47: 482130000 | E47: 485873000 | F47: 500343000 | G47: 514405000 | H47: 523964000 | I47: 559151000 | J47: 572754000 | K47: 611289000
A48: Net Income | B48: 16022000 | C48: 16363000 | D48: 14694000 | E48: 13643000 | F48: 9862000 | G48: 6670000 | H48: 14881000 | I48: 13510000 | J48: 13673000 | K48: 11680000
A51: =A13 -> Report Date | B51: =B13 -> 01/31/2015 | C51: =C13 -> 01/31/2016 | D51: =D13 -> 01/31/2017 | E51: =E13 -> 01/31/2018 | F51: =F13 -> 01/31/2019 | G51: =G13 -> 01/31/2020 | H51: =H13 -> 01/31/2021 | ... K51: =K13 -> 01/31/2024 | L51: Average
A52: =A15 -> Sales Revenue | C52: =C15/B15-1 -> -0.0074964384 | D52: =D15/C15-1 -> 0.0056475573 | E52: =E15/D15-1 -> 0.030009329 | F52: =F15/E15-1 -> 0.029385127 | G52: =G15/F15-1 -> 0.018805516 | H52: =H15/G15-1 -> 0.067907741 | I52: =I15/H15-1 -> 0.022565301 | J52: =J15/I15-1 -> 0.067139048 | K52: =K15/J15-1 -> 0.060665378 | L52: =AVERAGE(C52:K52) -> 0.032736506
A53: =A16 -> Other Revenue | C53: =C16/B16-1 -> 0.027469316 | D53: =D16/C16-1 -> 0.29579067 | E53: =E16/D16-1 -> 0.0057067603 | F53: =F16/E16-1 -> -0.11043213 | G53: =G16/F16-1 -> -0.0093228656 | H53: =H16/G16-1 -> -0.029717682 | I53: =I16/H16-1 -> 0.27411945 | J53: =J16/I16-1 -> 0.083333333 | K53: =K16/J16-1 -> 0.014792899 | L53: =AVERAGE(C53:K53) -> 0.061304417
A54: =A17 -> Total Revenue | C54: =C17/B17-1 -> -0.0072500623 | D54: =D17/C17-1 -> 0.0077634663 | E54: =E17/D17-1 -> 0.029781445 | F54: =F17/E17-1 -> 0.02810472 | G54: =G17/F17-1 -> 0.018582634 | H54: =H17/G17-1 -> 0.067155377 | I54: =I17/H17-1 -> 0.024327954 | J54: =J17/I17-1 -> 0.067280194 | K54: =K17/J17-1 -> 0.06025955 | L54: =AVERAGE(C54:K54) -> 0.032889475
A55: =A18 -> Direct Costs | C55: =C18/B18-1 -> -0.011235709 | D55: =D18/C18-1 -> 0.000753496 | E55: =E18/D18-1 -> 0.033604978 | F55: =F18/E18-1 -> 0.031883041 | G55: =G18/F18-1 -> 0.024147355 | H55: =H18/G18-1 -> 0.065153761 | I55: =I18/H18-1 -> 0.020663074 | J55: =J18/I18-1 -> 0.080934732 | K55: =K18/J18-1 -> 0.05697607 | L55: =AVERAGE(C55:K55) -> 0.033653422
A56: =A19 -> Gross Profit | C56: =C19/B19-1 -> 0.0048189773 | D56: =D19/C19-1 -> 0.028651379 | E56: =E19/D19-1 -> 0.018697288 | F56: =F19/E19-1 -> 0.016991343 | G56: =G19/F19-1 -> 0.0019751518 | H56: =H19/G19-1 -> 0.073261234 | I56: =I19/H19-1 -> 0.035423089 | J56: =J19/I19-1 -> 0.026531436 | K56: =K19/J19-1 -> 0.070577632 | L56: =AVERAGE(C56:K56) -> 0.030769726
A57: =A20 -> Selling General & Admin | C57: =C20/B20-1 -> 0.038782676 | D57: =D20/C20-1 -> 0.049587288 | E57: =E20/D20-1 -> 0.045722757 | F57: =F20/E20-1 -> 0.0059806591 | G57: =G20/F20-1 -> 0.015343407 | H57: =H20/G20-1 -> 0.06891195 | I57: =I20/H20-1 -> 0.013105394 | J57: =J20/I20-1 -> 0.079176994 | K57: =K20/J20-1 -> 0.030132138 | L57: =AVERAGE(C57:K57) -> 0.038527029
...

Sheet common size IS
C6: =standardized!B13 -> 01/31/2015 | D6: =standardized!C13 -> 01/31/2016 | E6: =standardized!D13 -> 01/31/2017 | F6: =standardized!E13 -> 01/31/2018 | G6: =standardized!F13 -> 01/31/2019 | H6: =standardized!G13 -> 01/31/2020 | I6: =standardized!H13 -> 01/31/2021 | J6: =standardized!I13 -> 01/31/2022 | ... L6: =standardized!K13 -> 01/31/2024
B8: =standardized!A15 -> Sales Revenue | C8: =standardized!B15/standardized!B$17 -> 0.99295379 | D8: =standardized!C15/standardized!C$17 -> 0.99270736 | E8: =standardized!D15/standardized!D$17 -> 0.99062306 | F8: =standardized!E15/standardized!E$17 -> 0.99084228 | G8: =standardized!F15/standardized!F$17 -> 0.99207628 | H8: =standardized!G15/standardized!G$17 -> 0.99229336 | I8: =standardized!H15/standardized!H$17 -> 0.99299295 | J8: =standardized!I15/standardized!I$17 -> 0.99128422 | ... L8: =standardized!K15/standardized!K$17 -> 0.9915325 | M8: =AVERAGE(C8:L8) -> 0.99184589
B9: =standardized!A16 -> Other Revenue | C9: =standardized!B16/standardized!B$17 -> 0.0070462122 | D9: =standardized!C16/standardized!C$17 -> 0.0072926389 | E9: =standardized!D16/standardized!D$17 -> 0.0093769359 | F9: =standardized!E16/standardized!E$17 -> 0.0091577178 | G9: =standardized!F16/standardized!F$17 -> 0.0079237177 | H9: =standardized!G16/standardized!G$17 -> 0.0077066363 | I9: =standardized!H16/standardized!H$17 -> 0.0070070518 | J9: =standardized!I16/standardized!I$17 -> 0.0087157837 | ... L9: =standardized!K16/standardized!K$17 -> 0.0084675024 | M9: =AVERAGE(C9:L9) -> 0.0081541076
B10: =standardized!A17 -> Total Revenue | C10: =standardized!B17/standardized!B$17 -> 1 | D10: =standardized!C17/standardized!C$17 -> 1 | E10: =standardized!D17/standardized!D$17 -> 1 | F10: =standardized!E17/standardized!E$17 -> 1 | G10: =standardized!F17/standardized!F$17 -> 1 | H10: =standardized!G17/standardized!G$17 -> 1 | I10: =standardized!H17/standardized!H$17 -> 1 | J10: =standardized!I17/standardized!I$17 -> 1 | ... L10: =standardized!K17/standardized!K$17 -> 1 | M10: =AVERAGE(C10:L10) -> 1
B11: =standardized!A18 -> Direct Costs | C11: =standardized!B18/standardized!B$17 -> 0.7517456 | D11: =standardized!C18/standardized!C$17 -> 0.74872752 | E11: =standardized!D18/standardized!D$17 -> 0.7435194 | F11: =standardized!E18/standardized!E$17 -> 0.74628005 | G11: =standardized!F18/standardized!F$17 -> 0.74902266 | H11: =standardized!G18/standardized!G$17 -> 0.75311472 | I11: =standardized!H18/standardized!H$17 -> 0.75170213 | J11: =standardized!I18/standardized!I$17 -> 0.74901267 | ... L11: =standardized!K18/standardized!K$17 -> 0.75624609 | M11: =AVERAGE(C11:L11) -> 0.75079662
B12: =standardized!A19 -> Gross Profit | C12: =standardized!B19/standardized!B$17 -> 0.2482544 | D12: =standardized!C19/standardized!C$17 -> 0.25127248 | E12: =standardized!D19/standardized!D$17 -> 0.2564806 | F12: =standardized!E19/standardized!E$17 -> 0.25371995 | G12: =standardized!F19/standardized!F$17 -> 0.25097734 | H12: =standardized!G19/standardized!G$17 -> 0.24688528 | I12: =standardized!H19/standardized!H$17 -> 0.24829787 | J12: =standardized!I19/standardized!I$17 -> 0.25098733 | ... L12: =standardized!K19/standardized!K$17 -> 0.24375391 | M12: =AVERAGE(C12:L12) -> 0.24920338
B13: =standardized!A20 -> Selling General & Admin | C13: =standardized!B20/standardized!B$17 -> 0.19235624 | D13: =standardized!C20/standardized!C$17 -> 0.20127559 | E13: =standardized!D20/standardized!D$17 -> 0.20962885 | F13: =standardized!E20/standardized!E$17 -> 0.21287397 | G13: =standardized!F20/standardized!F$17 -> 0.20829308 | H13: =standardized!G20/standardized!G$17 -> 0.20763068 | I13: =standardized!H20/standardized!H$17 -> 0.20797244 | J13: =standardized!I20/standardized!I$17 -> 0.20569389 | ... L13: =standardized!K20/standardized!K$17 -> 0.20207676 | M13: =AVERAGE(C13:L13) -> 0.20557882
B14: =standardized!A21 -> Total Indirect Operating Costs | C14: =standardized!B21/standardized!B$17 -> 0.19235624 | D14: =standardized!C21/standardized!C$17 -> 0.20127559 | E14: =standardized!D21/standardized!D$17 -> 0.20962885 | F14: =standardized!E21/standardized!E$17 -> 0.21287397 | G14: =standardized!F21/standardized!F$17 -> 0.20829308 | H14: =standardized!G21/standardized!G$17 -> 0.20763068 | I14: =standardized!H21/standardized!H$17 -> 0.20797244 | J14: =standardized!I21/standardized!I$17 -> 0.20569389 | ... L14: =standardized!K21/standardized!K$17 -> 0.20207676 | M14: =AVERAGE(C14:L14) -> 0.20557882
B15: =standardized!A22 -> Operating Income | C15: =standardized!B22/standardized!B$17 -> 0.055898166 | D15: =standardized!C22/standardized!C$17 -> 0.049996889 | E15: =standardized!D22/standardized!D$17 -> 0.046851749 | F15: =standardized!E22/standardized!E$17 -> 0.04084598 | G15: =standardized!F22/standardized!F$17 -> 0.042684266 | H15: =standardized!G22/standardized!G$17 -> 0.039254605 | I15: =standardized!H22/standardized!H$17 -> 0.040325422 | J15: =standardized!I22/standardized!I$17 -> 0.045293442 | ... L15: =standardized!K22/standardized!K$17 -> 0.041677146 | M15: =AVERAGE(C15:L15) -> 0.043624557
B16: =standardized!A23 -> Interest Income | C16: =standardized!B23/standardized!B$17 -> -0.0048347476 | D16: =standardized!C23/standardized!C$17 -> -0.0051168772 | E16: =standardized!D23/standardized!D$17 -> -0.0046658283 | F16: =standardized!E23/standardized!E$17 -> -0.0043530138 | G16: =standardized!F23/standardized!F$17 -> -0.0041387623 | H16: =standardized!G23/standardized!G$17 -> -0.0045995526 | I16: =standardized!H23/standardized!H$17 -> -0.0039238059 | J16: =standardized!I23/standardized!I$17 -> -0.0032055647 | ... L16: =standardized!K23/standardized!K$17 -> -0.0032972035 | M16: =AVERAGE(C16:L16) -> -0.0041201009
B17: =standardized!A24 -> Other Non-Operating Income | C17: =standardized!B24/standardized!B$17 -> 0 | D17: =standardized!C24/standardized!C$17 -> 0 | E17: =standardized!D24/standardized!D$17 -> 0 | F17: =standardized!E24/standardized!E$17 -> -0.0062677004 | G17: =standardized!F24/standardized!F$17 -> -0.016267338 | H17: =standardized!G24/standardized!G$17 -> 0.003736898 | I17: =standardized!H24/standardized!H$17 -> 0.00037556939 | J17: =standardized!I24/standardized!I$17 -> -0.009445591 | ... L17: =standardized!K24/standardized!K$17 -> -0.0046703954 | M17: =AVERAGE(C17:L17) -> -0.0035054552
B18: =standardized!A25 -> Total Non-Operating Income | C18: =standardized!B25/standardized!B$17 -> -0.0048347476 | D18: =standardized!C25/standardized!C$17 -> -0.0051168772 | E18: =standardized!D25/standardized!D$17 -> -0.0046658283 | F18: =standardized!E25/standardized!E$17 -> -0.010620714 | G18: =standardized!F25/standardized!F$17 -> -0.0204061 | H18: =standardized!G25/standardized!G$17 -> -0.00086265469 | I18: =standardized!H25/standardized!H$17 -> -0.0035482365 | J18: =standardized!I25/standardized!I$17 -> -0.012651156 | ... L18: =standardized!K25/standardized!K$17 -> -0.0079675988 | M18: =AVERAGE(C18:L18) -> -0.0076255561
B19: =standardized!A26 -> Earnings Before Tax | C19: =standardized!B26/standardized!B$17 -> 0.051063418 | D19: =standardized!C26/standardized!C$17 -> 0.044880012 | E19: =standardized!D26/standardized!D$17 -> 0.042185921 | F19: =standardized!E26/standardized!E$17 -> 0.030225265 | G19: =standardized!F26/standardized!F$17 -> 0.022278166 | H19: =standardized!G26/standardized!G$17 -> 0.038391951 | I19: =standardized!H26/standardized!H$17 -> 0.036777185 | J19: =standardized!I26/standardized!I$17 -> 0.032642286 | ... L19: =standardized!K26/standardized!K$17 -> 0.033709547 | M19: =AVERAGE(C19:L19) -> 0.035999001
... B22: =standardized!A29 -> Net Income | C22: =standardized!B29/standardized!B$17 -> 0.033692919 | D22: =standardized!C29/standardized!C$17 -> 0.030477257 | E22: =standardized!D29/standardized!D$17 -> 0.028079354 | F22: =standardized!E29/standardized!E$17 -> 0.019710479 | G22: =standardized!F29/standardized!F$17 -> 0.012966437 | H22: =standardized!G29/standardized!G$17 -> 0.028400806 | I22: =standardized!H29/standardized!H$17 -> 0.024161631 | J22: =standardized!I29/standardized!I$17 -> 0.023872378 | ... L22: =standardized!K29/standardized!K$17 -> 0.023932112 | M22: =AVERAGE(C22:L22) -> 0.024440054

Sheet Balance sheet
A4: Powered by Clearbit
A5: Walmart Inc (NYS: WMT)
A7: Exchange rate used is that of the Year End reported date
A10: Standardized Annual Balance Sheet
A11: Report Date | B11: 01/31/2015 | C11: 01/31/2016 | D11: 01/31/2017 | E11: 01/31/2018 | F11: 01/31/2019 | G11: 01/31/2020 | H11: 01/31/2021 | I11: 01/31/2022 | J11: 01/31/2023 | K11: 01/31/2024
A13: Cash & Equivalents | B13: 9135000 | C13: 8705000 | D13: 6867000 | E13: 6756000 | F13: 7722000 | G13: 9465000 | H13: 17741000 | I13: 14760000 | J13: 8625000 | K13: 9867000
A14: Cash & Equivs & ST Investments | B14: 9135000 | C14: 8705000 | D14: 6867000 | E14: 6756000 | F14: 7722000 | G14: 9465000 | H14: 17741000 | I14: 14760000 | J14: 8625000 | K14: 9867000
A15: Receivables (ST) | B15: 6778000 | C15: 5624000 | D15: 5835000 | E15: 5614000 | F15: 6283000 | G15: 6284000 | H15: 6516000 | I15: 8280000 | J15: 7933000 | K15: 8796000
A16: Inventories | B16: 45141000 | C16: 44469000 | D16: 43046000 | E16: 43783000 | F16: 44269000 | G16: 44435000 | H16: 44949000 | I16: 56511000 | J16: 56576000 | K16: 54892000
A17: Discontinued Ops (ST Asset) | B17: 0 | C17: 0 | D17: 0 | E17: 0 | F17: 0 | G17: 0 | H17: 0 | I17: 0 | J17: 0 | K17: 3322000
A18: Other Current Assets | B18: 2224000 | C18: 1441000 | D18: 1941000 | E18: 3511000 | F18: 3623000 | G18: 1622000 | H18: 20861000 | I18: 1519000 | J18: 2521000 | K18: 0
A19: Total Current Assets | B19: 63278000 | C19: 60239000 | D19: 57689000 | E19: 59664000 | F19: 61897000 | G19: 61806000 | H19: 90067000 | I19: 81070000 | J19: 75655000 | K19: 76877000
A20: Gross Property Plant & Equip | B20: 177395000 | C20: 176958000 | D20: 179492000 | E20: 185154000 | F20: 185810000 | G20: 195028000 | H20: 180571000 | I20: 189324000 | J20: 202370000 | K20: 219859000
A21: Accumulated Depreciation | B21: 63115000 | C21: 66787000 | D21: 71782000 | E21: 77479000 | F21: 81493000 | G21: 89820000 | H21: 88370000 | I21: 94809000 | J21: 101610000 | K21: 109049000
A22: Net Property Plant & Equip | B22: 114280000 | C22: 110171000 | D22: 107710000 | E22: 107675000 | F22: 104317000 | G22: 105208000 | H22: 92201000 | I22: 94515000 | J22: 100760000 | K22: 110810000
A23: Intangible Assets | B23: 18102000 | C23: 16695000 | D23: 17037000 | E23: 18242000 | F23: 31181000 | G23: 31073000 | H23: 28983000 | I23: 29014000 | J23: 28174000 | K23: 28113000
A24: Other Assets | B24: 8046000 | C24: 12476000 | D24: 16389000 | E24: 18941000 | F24: 21900000 | G24: 38408000 | H24: 41245000 | I24: 40261000 | J24: 38608000 | K24: 36599000
... A63: Total Current Liabilities | B63: 69345000 | C63: 65272000 | D63: 64619000 | E63: 66928000 | F63: 78521000 | G63: 77477000 | H63: 77790000 | I63: 92645000 | J63: 87379000 | K63: 92198000
A66: =A11 -> Report Date | B66: =B11 -> 01/31/2015 | C66: =C11 -> 01/31/2016 | D66: =D11 -> 01/31/2017 | E66: =E11 -> 01/31/2018 | F66: =F11 -> 01/31/2019 | G66: =G11 -> 01/31/2020 | H66: =H11 -> 01/31/2021 | ... K66: =K11 -> 01/31/2024 | L66: average
A68: =A13 -> Cash & Equivalents | C68: =C13/B13-1 -> -0.047071702 | D68: =D13/C13-1 -> -0.21114302 | E68: =E13/D13-1 -> -0.016164264 | F68: =F13/E13-1 -> 0.14298401 | G68: =G13/F13-1 -> 0.22571873 | H68: =H13/G13-1 -> 0.87437929 | I68: =I13/H13-1 -> -0.16802886 | J68: =J13/I13-1 -> -0.41565041 | K68: =K13/J13-1 -> 0.144 | L68: =AVERAGE(C68:K68) -> 0.05878042
A69: =A14 -> Cash & Equivs & ST Investments | C69: =C14/B14-1 -> -0.047071702 | D69: =D14/C14-1 -> -0.21114302 | E69: =E14/D14-1 -> -0.016164264 | F69: =F14/E14-1 -> 0.14298401 | G69: =G14/F14-1 -> 0.22571873 | H69: =H14/G14-1 -> 0.87437929 | I69: =I14/H14-1 -> -0.16802886 | J69: =J14/I14-1 -> -0.41565041 | K69: =K14/J14-1 -> 0.144 | L69: =AVERAGE(C69:K69) -> 0.05878042
A70: =A15 -> Receivables (ST) | C70: =C15/B15-1 -> -0.17025671 | D70: =D15/C15-1 -> 0.037517781 | E70: =E15/D15-1 -> -0.037874893 | F70: =F15/E15-1 -> 0.11916637 | G70: =G15/F15-1 -> 0.00015915964 | H70: =H15/G15-1 -> 0.03691916 | I70: =I15/H15-1 -> 0.27071823 | J70: =J15/I15-1 -> -0.041908213 | K70: =K15/J15-1 -> 0.10878608 | L70: =AVERAGE(C70:K70) -> 0.035914107
A71: =A16 -> Inventories | C71: =C16/B16-1 -> -0.014886688 | D71: =D16/C16-1 -> -0.03199982 | E71: =E16/D16-1 -> 0.017121219 | F71: =F16/E16-1 -> 0.011100199 | G71: =G16/F16-1 -> 0.0037498023 | H71: =H16/G16-1 -> 0.011567458 | I71: =I16/H16-1 -> 0.25722485 | J71: =J16/I16-1 -> 0.0011502185 | K71: =K16/J16-1 -> -0.029765271 | L71: =AVERAGE(C71:K71) -> 0.025029108
A72: =A18 -> Other Current Assets | C72: =C18/B18-1 -> -0.35206835 | D72: =D18/C18-1 -> 0.34698126 | E72: =E18/D18-1 -> 0.80886141 | F72: =F18/E18-1 -> 0.031899744 | G72: =G18/F18-1 -> -0.55230472 | H72: =H18/G18-1 -> 11.861282 | I72: =I18/H18-1 -> -0.9271847 | J72: =J18/I18-1 -> 0.6596445 | K72: =K18/J18-1 -> -1 | L72: =AVERAGE(C72:K72) -> 1.2085679
A73: =A19 -> Total Current Assets | C73: =C19/B19-1 -> -0.04802617 | D73: =D19/C19-1 -> -0.04233138 | E73: =E19/D19-1 -> 0.034235296 | F73: =F19/E19-1 -> 0.037426254 | G73: =G19/F19-1 -> -0.0014701843 | H73: =H19/G19-1 -> 0.45725334 | I73: =I19/H19-1 -> -0.099892302 | J73: =J19/I19-1 -> -0.066794129 | K73: =K19/J19-1 -> 0.01615227 | L73: =AVERAGE(C73:K73) -> 0.031839222
A74: =A20 -> Gross Property Plant & Equip | C74: =C20/B20-1 -> -0.0024634291 | D74: =D20/C20-1 -> 0.014319782 | E74: =E20/D20-1 -> 0.031544581 | F74: =F20/E20-1 -> 0.0035429966 | G74: =G20/F20-1 -> 0.049609816 | H74: =H20/G20-1 -> -0.074127818 | I74: =I20/H20-1 -> 0.048474007 | J74: =J20/I20-1 -> 0.068908326 | K74: =K20/J20-1 -> 0.086420912 | L74: =AVERAGE(C74:K74) -> 0.025136575
A75: =A21 -> Accumulated Depreciation | C75: =C21/B21-1 -> 0.058179514 | D75: =D21/C21-1 -> 0.074790004 | E75: =E21/D21-1 -> 0.0793653 | F75: =F21/E21-1 -> 0.051807587 | G75: =G21/F21-1 -> 0.10218056 | H75: =H21/G21-1 -> -0.016143398 | I75: =I21/H21-1 -> 0.072864094 | J75: =J21/I21-1 -> 0.071733696 | K75: =K21/J21-1 -> 0.073211298 | L75: =AVERAGE(C75:K75) -> 0.06310985
A76: =A22 -> Net Property Plant & Equip | C76: =C22/B22-1 -> -0.035955548 | D76: =D22/C22-1 -> -0.022338002 | E76: =E22/D22-1 -> -0.00032494662 | F76: =F22/E22-1 -> -0.031186441 | G76: =G22/F22-1 -> 0.0085412732 | H76: =H22/G22-1 -> -0.12363128 | I76: =I22/H22-1 -> 0.025097342 | J76: =J22/I22-1 -> 0.066074168 | K76: =K22/J22-1 -> 0.099741961 | L76: =AVERAGE(C76:K76) -> -0.0015534973
A77: =A23 -> Intangible Assets | C77: =C23/B23-1 -> -0.077726218 | D77: =D23/C23-1 -> 0.020485175 | E77: =E23/D23-1 -> 0.070728415 | F77: =F23/E23-1 -> 0.70929723 | G77: =G23/F23-1 -> -0.0034636477 | H77: =H23/G23-1 -> -0.067260966 | I77: =I23/H23-1 -> 0.0010695925 | J77: =J23/I23-1 -> -0.028951541 | K77: =K23/J23-1 -> -0.0021651168 | L77: =AVERAGE(C77:K77) -> 0.069112547
A78: =A24 -> Other Assets | C78: =C24/B24-1 -> 0.55058414 | D78: =D24/C24-1 -> 0.31364219 | E78: =E24/D24-1 -> 0.1557142 | F78: =F24/E24-1 -> 0.15622195 | G78: =G24/F24-1 -> 0.75378995 | H78: =H24/G24-1 -> 0.07386482 | I78: =I24/H24-1 -> -0.023857437 | J78: =J24/I24-1 -> -0.041057102 | K78: =K24/J24-1 -> -0.052035847 | L78: =AVERAGE(C78:K78) -> 0.20965187
A79: =A25 -> Total Assets | C79: =C25/B25-1 -> -0.020249772 | D79: =D25/C25-1 -> -0.0037879357 | E79: =E25/D25-1 -> 0.028653338 | F79: =F25/E25-1 -> 0.072231838 | G79: =G25/F25-1 -> 0.078433161 | H79: =H25/G25-1 -> 0.067658936 | I79: =I25/H25-1 -> -0.030242063 | J79: =J25/I25-1 -> -0.006791636 | K79: =K25/J25-1 -> 0.037837638 | L79: =AVERAGE(C79:K79) -> 0.024860389
A80: =A26 -> Accounts Payable & Accrued Exps | C80: =C26/B26-1 -> 0.00054623355 | D80: =D26/C26-1 -> 0.074946686 | E80: =E26/D26-1 -> 0.060849416 | F80: =F26/E26-1 -> 0.01306065 | G80: =G26/F26-1 -> -0.0023037732 | H80: =H26/G26-1 -> 0.070249708 | I80: =I26/H26-1 -> 0.10078141 | J80: =J26/I26-1 -> 0.04416273 | K80: =K26/J26-1 -> 0.033342558 | L80: =AVERAGE(C80:K80) -> 0.043959513
A81: =A27 -> Accounts Payable | C81: =C27/B27-1 -> 0.0020046863 | D81: =D27/C27-1 -> 0.076545327 | E81: =E27/D27-1 -> 0.1124466 | F81: =F27/E27-1 -> 0.021001475 | G81: =G27/F27-1 -> -0.0018487038 | H81: =H27/G27-1 -> 0.046154174 | I81: =I27/H27-1 -> 0.12453959 | J81: =J27/I27-1 -> -0.02748774 | K81: =K27/J27-1 -> 0.057124781 | L81: =AVERAGE(C81:K81) -> 0.04560891
A82: =A28 -> Accrued Expenses | C82: =C28/B28-1 -> -0.0022307044 | D82: =D28/C28-1 -> 0.071889905 | E82: =E28/D28-1 -> -0.038238702 | F82: =F28/E28-1 -> -0.0045783133 | G82: =G28/F28-1 -> -0.0033405955 | H82: =H28/G28-1 -> 0.12523074 | I82: =I28/H28-1 -> 0.0503799 | J82: =J28/I28-1 -> 0.20689655 | K82: =K28/J28-1 -> -0.01018219 | L82: =AVERAGE(C82:K82) -> 0.043980732
A83: =A29 -> Current Debt | C83: =C29/B29-1 -> -0.14823493 | D83: =D29/C29-1 -> -0.38474234 | E83: =E29/D29-1 -> 1.681073 | F83: =F29/E29-1 -> -0.21056142 | G83: =G29/F29-1 -> -0.16392057 | H83: =H29/G29-1 -> -0.43759474 | I83: =I29/H29-1 -> -0.037735849 | J83: =J29/I29-1 -> 0.42016807 | K83: =K29/J29-1 -> -0.052158668 | L83: =AVERAGE(C83:K83) -> 0.074032507
A84: =A30 -> Current Lease Obligations | C84: =C30/B30-1 -> 0.91986063 | D84: =D30/C30-1 -> 0.025408348 | E84: =E30/D30-1 -> 0.18053097 | F84: =F30/E30-1 -> 0.092953523 | G84: =G30/F30-1 -> -0.29903978 | H84: =H30/G30-1 -> -0.039138943 | I84: =I30/H30-1 -> 0.040733198 | J84: =J30/I30-1 -> 0.10958904 | K84: =K30/J30-1 -> 0.27865961 | L84: =AVERAGE(C84:K84) -> 0.14550629
A85: =#REF! -> #REF! | C85: =#REF!/#REF!-1 -> #REF! | D85: =#REF!/#REF!-1 -> #REF! | E85: =#REF!/#REF!-1 -> #REF! | F85: =#REF!/#REF!-1 -> #REF! | G85: =#REF!/#REF!-1 -> #REF! | H85: =#REF!/#REF!-1 -> #REF! | I85: =#REF!/#REF!-1 -> #REF! | J85: =#REF!/#REF!-1 -> #REF! | K85: =#REF!/#REF!-1 -> #REF! | L85: =AVERAGE(C85:K85) -> #REF!
A86: =A31 -> Other Current Liabilities | C86: =C31/B31-1 -> #DIV/0! | D86: =D31/C31-1 -> #DIV/0! | E86: =E31/D31-1 -> #DIV/0! | F86: =F31/E31-1 -> -0.042141795 | G86: =G31/F31-1 -> 0.95807453 | H86: =H31/G31-1 -> 3.3642612 | I86: =I31/H31-1 -> -0.75390672 | J86: =J31/I31-1 -> -0.025104603 | K86: =K31/J31-1 -> -0.62458975 | L86: =AVERAGE(G86:K86) -> 0.58374693
A87: =A32 -> Total Current Liabilities | C87: =C32/B32-1 -> -0.01000429 | D87: =D32/C32-1 -> 0.035732524 | E87: =E32/D32-1 -> 0.17321599 | F87: =F32/E32-1 -> -0.013295806 | G87: =G32/F32-1 -> 0.0040399086 | H87: =H32/G32-1 -> 0.19096285 | I87: =I32/H32-1 -> -0.056840628 | J87: =J32/I32-1 -> 0.055150551 | K87: =K32/J32-1 -> 0.0023536302 | L87: =AVERAGE(C87:K87) -> 0.042368304
A88: =A33 -> LT Debt & Leases | C88: =C33/B33-1 -> 0.00773597 | D88: =D33/C33-1 -> -0.045696116 | E88: =E33/D33-1 -> -0.12358989 | F88: =F33/E33-1 -> 0.36328581 | G88: =G33/F33-1 -> -0.043463538 | H88: =H33/G33-1 -> -0.062056184 | I88: =I33/H33-1 -> -0.13174663 | J88: =J33/I33-1 -> 0.0098447848 | K88: =K33/J33-1 -> 0.059480401 | L88: =AVERAGE(C88:K88) -> 0.0037549565
...

Sheet common size balance sheet 
C6: ='Balance sheet'!B11 -> 01/31/2015 | D6: ='Balance sheet'!C11 -> 01/31/2016 | E6: ='Balance sheet'!D11 -> 01/31/2017 | F6: ='Balance sheet'!E11 -> 01/31/2018 | G6: ='Balance sheet'!F11 -> 01/31/2019 | H6: ='Balance sheet'!G11 -> 01/31/2020 | I6: ='Balance sheet'!H11 -> 01/31/2021 | J6: ='Balance sheet'!I11 -> 01/31/2022 | ... L6: ='Balance sheet'!K11 -> 01/31/2024
B8: ='Balance sheet'!$A13 -> Cash & Equivalents | C8: ='Balance sheet'!B13/'Balance sheet'!$B$25 -> 0.04484404 | D8: ='Balance sheet'!C13/'Balance sheet'!$C$25 -> 0.043616376 | E8: ='Balance sheet'!D13/'Balance sheet'!$D$25 -> 0.03453791 | F8: ='Balance sheet'!E13/'Balance sheet'!$E$25 -> 0.033033121 | G8: ='Balance sheet'!F13/'Balance sheet'!$F$25 -> 0.035212841 | H8: ='Balance sheet'!G13/'Balance sheet'!$G$25 -> 0.040021988 | I8: ='Balance sheet'!H13/'Balance sheet'!$H$25 -> 0.070262499 | J8: ='Balance sheet'!I13/'Balance sheet'!$I$25 -> 0.060279343 | K8: ='Balance sheet'!J13/'Balance sheet'!$J$25 -> 0.035465076 | L8: ='Balance sheet'!K13/'Balance sheet'!$K$25 -> 0.039092865
B9: ='Balance sheet'!$A14 -> Cash & Equivs & ST Investments | C9: ='Balance sheet'!B14/'Balance sheet'!$B$25 -> 0.04484404 | D9: ='Balance sheet'!C14/'Balance sheet'!$C$25 -> 0.043616376 | E9: ='Balance sheet'!D14/'Balance sheet'!$D$25 -> 0.03453791 | F9: ='Balance sheet'!E14/'Balance sheet'!$E$25 -> 0.033033121 | G9: ='Balance sheet'!F14/'Balance sheet'!$F$25 -> 0.035212841 | H9: ='Balance sheet'!G14/'Balance sheet'!$G$25 -> 0.040021988 | I9: ='Balance sheet'!H14/'Balance sheet'!$H$25 -> 0.070262499 | J9: ='Balance sheet'!I14/'Balance sheet'!$I$25 -> 0.060279343 | K9: ='Balance sheet'!J14/'Balance sheet'!$J$25 -> 0.035465076 | L9: ='Balance sheet'!K14/'Balance sheet'!$K$25 -> 0.039092865
B10: ='Balance sheet'!$A15 -> Receivables (ST) | C10: ='Balance sheet'!B15/'Balance sheet'!$B$25 -> 0.033273443 | D10: ='Balance sheet'!C15/'Balance sheet'!$C$25 -> 0.028179035 | E10: ='Balance sheet'!D15/'Balance sheet'!$D$25 -> 0.029347416 | F10: ='Balance sheet'!E15/'Balance sheet'!$E$25 -> 0.02744937 | G10: ='Balance sheet'!F15/'Balance sheet'!$F$25 -> 0.028650904 | H10: ='Balance sheet'!G15/'Balance sheet'!$G$25 -> 0.026571386 | I10: ='Balance sheet'!H15/'Balance sheet'!$H$25 -> 0.025806349 | J10: ='Balance sheet'!I15/'Balance sheet'!$I$25 -> 0.033815241 | K10: ='Balance sheet'!J15/'Balance sheet'!$J$25 -> 0.032619646 | L10: ='Balance sheet'!K15/'Balance sheet'!$K$25 -> 0.034849583
B11: ='Balance sheet'!$A16 -> Inventories | C11: ='Balance sheet'!B16/'Balance sheet'!$B$25 -> 0.22159877 | D11: ='Balance sheet'!C16/'Balance sheet'!$C$25 -> 0.22281179 | E11: ='Balance sheet'!D16/'Balance sheet'!$D$25 -> 0.21650195 | F11: ='Balance sheet'!E16/'Balance sheet'!$E$25 -> 0.21407477 | G11: ='Balance sheet'!F16/'Balance sheet'!$F$25 -> 0.20186963 | H11: ='Balance sheet'!G16/'Balance sheet'!$G$25 -> 0.18788981 | I11: ='Balance sheet'!H16/'Balance sheet'!$H$25 -> 0.17801866 | J11: ='Balance sheet'!I16/'Balance sheet'!$I$25 -> 0.23078902 | K11: ='Balance sheet'!J16/'Balance sheet'!$J$25 -> 0.23263445 | L11: ='Balance sheet'!K16/'Balance sheet'!$K$25 -> 0.21748105
B12: ='Balance sheet'!$A17 -> Discontinued Ops (ST Asset) | C12: ='Balance sheet'!B17/'Balance sheet'!$B$25 -> 0 | D12: ='Balance sheet'!C17/'Balance sheet'!$C$25 -> 0 | E12: ='Balance sheet'!D17/'Balance sheet'!$D$25 -> 0 | F12: ='Balance sheet'!E17/'Balance sheet'!$E$25 -> 0 | G12: ='Balance sheet'!F17/'Balance sheet'!$F$25 -> 0 | H12: ='Balance sheet'!G17/'Balance sheet'!$G$25 -> 0 | I12: ='Balance sheet'!H17/'Balance sheet'!$H$25 -> 0 | J12: ='Balance sheet'!I17/'Balance sheet'!$I$25 -> 0 | K12: ='Balance sheet'!J17/'Balance sheet'!$J$25 -> 0 | L12: ='Balance sheet'!K17/'Balance sheet'!$K$25 -> 0.0131617
B13: ='Balance sheet'!$A18 -> Other Current Assets | C13: ='Balance sheet'!B18/'Balance sheet'!$B$25 -> 0.010917695 | D13: ='Balance sheet'!C18/'Balance sheet'!$C$25 -> 0.0072201262 | E13: ='Balance sheet'!D18/'Balance sheet'!$D$25 -> 0.0097623538 | F13: ='Balance sheet'!E18/'Balance sheet'!$E$25 -> 0.017166857 | G13: ='Balance sheet'!F18/'Balance sheet'!$F$25 -> 0.016521125 | H13: ='Balance sheet'!G18/'Balance sheet'!$G$25 -> 0.006858496 | I13: ='Balance sheet'!H18/'Balance sheet'!$H$25 -> 0.082619131 | J13: ='Balance sheet'!I18/'Balance sheet'!$I$25 -> 0.0062035449 | K13: ='Balance sheet'!J18/'Balance sheet'!$J$25 -> 0.010366082 | L13: ='Balance sheet'!K18/'Balance sheet'!$K$25 -> 0
B14: ='Balance sheet'!$A19 -> Total Current Assets | C14: ='Balance sheet'!B19/'Balance sheet'!$B$25 -> 0.31063395 | D14: ='Balance sheet'!C19/'Balance sheet'!$C$25 -> 0.30182733 | E14: ='Balance sheet'!D19/'Balance sheet'!$D$25 -> 0.29014963 | F14: ='Balance sheet'!E19/'Balance sheet'!$E$25 -> 0.29172412 | G14: ='Balance sheet'!F19/'Balance sheet'!$F$25 -> 0.2822545 | H14: ='Balance sheet'!G19/'Balance sheet'!$G$25 -> 0.26134168 | I14: ='Balance sheet'!H19/'Balance sheet'!$H$25 -> 0.35670664 | J14: ='Balance sheet'!I19/'Balance sheet'!$I$25 -> 0.33108715 | K14: ='Balance sheet'!J19/'Balance sheet'!$J$25 -> 0.31108525 | L14: ='Balance sheet'!K19/'Balance sheet'!$K$25 -> 0.3045852
B15: ='Balance sheet'!$A20 -> Gross Property Plant & Equip | C15: ='Balance sheet'!B20/'Balance sheet'!$B$25 -> 0.87083837 | D15: ='Balance sheet'!C20/'Balance sheet'!$C$25 -> 0.88664753 | E15: ='Balance sheet'!D20/'Balance sheet'!$D$25 -> 0.90276374 | F15: ='Balance sheet'!E20/'Balance sheet'!$E$25 -> 0.90530114 | G15: ='Balance sheet'!F20/'Balance sheet'!$F$25 -> 0.84730614 | H15: ='Balance sheet'!G20/'Balance sheet'!$G$25 -> 0.82466014 | I15: ='Balance sheet'!H20/'Balance sheet'!$H$25 -> 0.715144 | J15: ='Balance sheet'!I20/'Balance sheet'!$I$25 -> 0.77319284 | K15: ='Balance sheet'!J20/'Balance sheet'!$J$25 -> 0.83212375 | L15: ='Balance sheet'!K20/'Balance sheet'!$K$25 -> 0.87107714
B16: ='Balance sheet'!$A21 -> Accumulated Depreciation | C16: ='Balance sheet'!B21/'Balance sheet'!$B$25 -> 0.30983378 | D16: ='Balance sheet'!C21/'Balance sheet'!$C$25 -> 0.33463606 | E16: ='Balance sheet'!D21/'Balance sheet'!$D$25 -> 0.36103106 | F16: ='Balance sheet'!E21/'Balance sheet'!$E$25 -> 0.37882966 | G16: ='Balance sheet'!F21/'Balance sheet'!$F$25 -> 0.37161358 | H16: ='Balance sheet'!G21/'Balance sheet'!$G$25 -> 0.37979661 | I16: ='Balance sheet'!H21/'Balance sheet'!$H$25 -> 0.34998574 | J16: ='Balance sheet'!I21/'Balance sheet'!$I$25 -> 0.38719677 | K16: ='Balance sheet'!J21/'Balance sheet'!$J$25 -> 0.41780943 | L16: ='Balance sheet'!K21/'Balance sheet'!$K$25 -> 0.43205005
B17: ='Balance sheet'!$A22 -> Net Property Plant & Equip | C17: ='Balance sheet'!B22/'Balance sheet'!$B$25 -> 0.56100459 | D17: ='Balance sheet'!C22/'Balance sheet'!$C$25 -> 0.55201146 | E17: ='Balance sheet'!D22/'Balance sheet'!$D$25 -> 0.54173268 | F17: ='Balance sheet'!E22/'Balance sheet'!$E$25 -> 0.52647148 | G17: ='Balance sheet'!F22/'Balance sheet'!$F$25 -> 0.47569256 | H17: ='Balance sheet'!G22/'Balance sheet'!$G$25 -> 0.44486353 | I17: ='Balance sheet'!H22/'Balance sheet'!$H$25 -> 0.36515826 | J17: ='Balance sheet'!I22/'Balance sheet'!$I$25 -> 0.38599608 | K17: ='Balance sheet'!J22/'Balance sheet'!$J$25 -> 0.41431432 | L17: ='Balance sheet'!K22/'Balance sheet'!$K$25 -> 0.4390271
B18: ='Balance sheet'!$A23 -> Intangible Assets | C18: ='Balance sheet'!B23/'Balance sheet'!$B$25 -> 0.088863362 | D18: ='Balance sheet'!C23/'Balance sheet'!$C$25 -> 0.083650247 | E18: ='Balance sheet'!D23/'Balance sheet'!$D$25 -> 0.085688419 | F18: ='Balance sheet'!E23/'Balance sheet'!$E$25 -> 0.089193339 | G18: ='Balance sheet'!F23/'Balance sheet'!$F$25 -> 0.14218746 | H18: ='Balance sheet'!G23/'Balance sheet'!$G$25 -> 0.13138967 | I18: ='Balance sheet'!H23/'Balance sheet'!$H$25 -> 0.11478598 | J18: ='Balance sheet'!I23/'Balance sheet'!$I$25 -> 0.1184922 | K18: ='Balance sheet'!J23/'Balance sheet'!$J$25 -> 0.11584847 | L18: ='Balance sheet'!K23/'Balance sheet'!$K$25 -> 0.11138317
B19: ='Balance sheet'!$A24 -> Other Assets | C19: ='Balance sheet'!B24/'Balance sheet'!$B$25 -> 0.0394981 | D19: ='Balance sheet'!C24/'Balance sheet'!$C$25 -> 0.06251096 | E19: ='Balance sheet'!D24/'Balance sheet'!$D$25 -> 0.082429272 | F19: ='Balance sheet'!E24/'Balance sheet'!$E$25 -> 0.092611064 | G19: ='Balance sheet'!F24/'Balance sheet'!$F$25 -> 0.099865478 | H19: ='Balance sheet'!G24/'Balance sheet'!$G$25 -> 0.16240512 | I19: ='Balance sheet'!H24/'Balance sheet'!$H$25 -> 0.16334912 | J19: ='Balance sheet'!I24/'Balance sheet'!$I$25 -> 0.16442457 | K19: ='Balance sheet'!J24/'Balance sheet'!$J$25 -> 0.15875196 | L19: ='Balance sheet'!K24/'Balance sheet'!$K$25 -> 0.14500454
... B39: ='Balance sheet'!$A44 -> Total Liabilities & Equity | C39: ='Balance sheet'!B44/'Balance sheet'!$B$25 -> 1 | D39: ='Balance sheet'!C44/'Balance sheet'!$C$25 -> 1 | E39: ='Balance sheet'!D44/'Balance sheet'!$D$25 -> 1 | F39: ='Balance sheet'!E44/'Balance sheet'!$E$25 -> 1 | G39: ='Balance sheet'!F44/'Balance sheet'!$F$25 -> 1 | H39: ='Balance sheet'!G44/'Balance sheet'!$G$25 -> 1 | I39: ='Balance sheet'!H44/'Balance sheet'!$H$25 -> 1 | J39: ='Balance sheet'!I44/'Balance sheet'!$I$25 -> 1 | K39: ='Balance sheet'!J44/'Balance sheet'!$J$25 -> 1 | L39: ='Balance sheet'!K44/'Balance sheet'!$K$25 -> 1

Sheet financial ratios
A3: Profitability ratios
A5: Report Date | C5: =standardized!B13 -> 01/31/2015 | D5: =standardized!C13 -> 01/31/2016 | E5: =standardized!D13 -> 01/31/2017 | F5: =standardized!E13 -> 01/31/2018 | G5: =standardized!F13 -> 01/31/2019 | H5: =standardized!G13 -> 01/31/2020 | I5: =standardized!H13 -> 01/31/2021 | J5: =standardized!I13 -> 01/31/2022 | ... L5: =standardized!K13 -> 01/31/2024
A6: Net Profit Margin | C6: =standardized!B29/standardized!B17 -> 0.033692919 | D6: =standardized!C29/standardized!C17 -> 0.030477257 | E6: =standardized!D29/standardized!D17 -> 0.028079354 | F6: =standardized!E29/standardized!E17 -> 0.019710479 | G6: =standardized!F29/standardized!F17 -> 0.012966437 | H6: =standardized!G29/standardized!G17 -> 0.028400806 | I6: =standardized!H29/standardized!H17 -> 0.024161631 | J6: =standardized!I29/standardized!I17 -> 0.023872378 | ... L6: =standardized!K29/standardized!K17 -> 0.023932112
A7: Gross Profit Margin | C7: =standardized!B19/standardized!B17 -> 0.2482544 | D7: =standardized!C19/standardized!C17 -> 0.25127248 | E7: =standardized!D19/standardized!D17 -> 0.2564806 | F7: =standardized!E19/standardized!E17 -> 0.25371995 | G7: =standardized!F19/standardized!F17 -> 0.25097734 | H7: =standardized!G19/standardized!G17 -> 0.24688528 | I7: =standardized!H19/standardized!H17 -> 0.24829787 | J7: =standardized!I19/standardized!I17 -> 0.25098733 | ... L7: =standardized!K19/standardized!K17 -> 0.24375391
A8: Operating Income | C8: =standardized!B22/standardized!B17 -> 0.055898166 | D8: =standardized!C22/standardized!C17 -> 0.049996889 | E8: =standardized!D22/standardized!D17 -> 0.046851749 | F8: =standardized!E22/standardized!E17 -> 0.04084598 | G8: =standardized!F22/standardized!F17 -> 0.042684266 | H8: =standardized!G22/standardized!G17 -> 0.039254605 | I8: =standardized!H22/standardized!H17 -> 0.040325422 | J8: =standardized!I22/standardized!I17 -> 0.045293442 | ... L8: =standardized!K22/standardized!K17 -> 0.041677146
A9: Return On Assets | C9: =standardized!B29/'Balance sheet'!B25 -> 0.080326549 | D9: =standardized!C29/'Balance sheet'!C25 -> 0.073624243 | E9: =standardized!D29/'Balance sheet'!D25 -> 0.068618132 | F9: =standardized!E29/'Balance sheet'!E25 -> 0.048219751 | G9: =standardized!F29/'Balance sheet'!F25 -> 0.03041565 | H9: =standardized!G29/'Balance sheet'!G25 -> 0.062923106 | I9: =standardized!H29/'Balance sheet'!H25 -> 0.053505798 | J9: =standardized!I29/'Balance sheet'!I25 -> 0.055840072 | ... L9: =standardized!K29/'Balance sheet'!K25 -> 0.061454285
A10: Return on equity | C10: =standardized!B29/'Balance sheet'!B43 -> 0.20103447 | D10: =standardized!C29/'Balance sheet'!C43 -> 0.18242992 | E10: =standardized!D29/'Balance sheet'!D43 -> 0.17536441 | F10: =standardized!E29/'Balance sheet'!E43 -> 0.1266486 | G10: =standardized!F29/'Balance sheet'!F43 -> 0.092005076 | H10: =standardized!G29/'Balance sheet'!G43 -> 0.19929288 | I10: =standardized!H29/'Balance sheet'!H43 -> 0.1669447 | J10: =standardized!I29/'Balance sheet'!I43 -> 0.16423432 | ... L10: =standardized!K29/'Balance sheet'!K43 -> 0.18496083
A11: Liquidity Ratio
A12: =A5 -> Report Date | B12: =B5 -> 0 | C12: =C5 -> 01/31/2015 | D12: =D5 -> 01/31/2016 | E12: =E5 -> 01/31/2017 | F12: =F5 -> 01/31/2018 | G12: =G5 -> 01/31/2019 | H12: =H5 -> 01/31/2020 | ... L12: =L5 -> 01/31/2024
A13: Current Ratio | C13: ='Balance sheet'!B19/'Balance sheet'!B32 -> 0.96945091 | D13: ='Balance sheet'!C19/'Balance sheet'!C32 -> 0.93221808 | E13: ='Balance sheet'!D19/'Balance sheet'!D32 -> 0.86195613 | F13: ='Balance sheet'!E19/'Balance sheet'!E32 -> 0.75984768 | G13: ='Balance sheet'!F19/'Balance sheet'!F32 -> 0.79890806 | H13: ='Balance sheet'!G19/'Balance sheet'!G32 -> 0.79452372 | I13: ='Balance sheet'!H19/'Balance sheet'!H32 -> 0.97217335 | J13: ='Balance sheet'!I19/'Balance sheet'!I32 -> 0.9277973 | ... L13: ='Balance sheet'!K19/'Balance sheet'!K32 -> 0.83186712
A14: Quick Ratios | C14: =('Balance sheet'!B19-'Balance sheet'!B16)/'Balance sheet'!B32 -> 0.277868 | D14: =('Balance sheet'!C19-'Balance sheet'!C16)/'Balance sheet'!C32 -> 0.24404587 | E14: =('Balance sheet'!D19-'Balance sheet'!D16)/'Balance sheet'!D32 -> 0.21878735 | F14: =('Balance sheet'!E19-'Balance sheet'!E16)/'Balance sheet'!E32 -> 0.20225163 | G14: =('Balance sheet'!F19-'Balance sheet'!F16)/'Balance sheet'!F32 -> 0.22752559 | H14: =('Balance sheet'!G19-'Balance sheet'!G16)/'Balance sheet'!G32 -> 0.22330634 | I14: =('Balance sheet'!H19-'Balance sheet'!H16)/'Balance sheet'!H32 -> 0.48699876 | J14: =('Balance sheet'!I19-'Balance sheet'!I16)/'Balance sheet'!I32 -> 0.28106296 | ... L14: =('Balance sheet'!K19-'Balance sheet'!K16)/'Balance sheet'!K32 -> 0.23789428
A15: Cash Ratio | C15: ='Balance sheet'!B13/'Balance sheet'!B32 -> 0.13995281 | D15: ='Balance sheet'!C13/'Balance sheet'!C32 -> 0.1347127 | E15: ='Balance sheet'!D13/'Balance sheet'!D32 -> 0.1026028 | F15: ='Balance sheet'!E13/'Balance sheet'!E32 -> 0.086040677 | G15: ='Balance sheet'!F13/'Balance sheet'!F32 -> 0.099668289 | H15: ='Balance sheet'!G13/'Balance sheet'!G32 -> 0.12167374 | I15: ='Balance sheet'!H13/'Balance sheet'!H32 -> 0.19149441 | J15: ='Balance sheet'!I13/'Balance sheet'!I32 -> 0.16891931 | ... L15: ='Balance sheet'!K13/'Balance sheet'!K32 -> 0.10676838
A16: Leverage Ratio
A17: Debt to Equity Ratio | C17: ='Balance sheet'!B36/'Balance sheet'!B43 -> 1.5027152 | D17: ='Balance sheet'!C36/'Balance sheet'!C43 -> 1.4778512 | E17: ='Balance sheet'!D36/'Balance sheet'!D43 -> 1.555657 | F17: ='Balance sheet'!E36/'Balance sheet'!E43 -> 1.6264881 | G17: ='Balance sheet'!F36/'Balance sheet'!F43 -> 2.0249255 | H17: ='Balance sheet'!G36/'Balance sheet'!G43 -> 2.1672448 | I17: ='Balance sheet'!H36/'Balance sheet'!H43 -> 2.1201236 | J17: ='Balance sheet'!I36/'Balance sheet'!I43 -> 1.9411553 | ... L17: ='Balance sheet'!K36/'Balance sheet'!K43 -> 2.0097304
A18: Debt Ratio | C18: =SUM('Balance sheet'!B29,'Balance sheet'!B30,'Balance sheet'!B33)/'Balance sheet'!B19 -> 0.79618509 | D18: =SUM('Balance sheet'!C29,'Balance sheet'!C30,'Balance sheet'!C33)/'Balance sheet'!C19 -> 0.83059148 | E18: =SUM('Balance sheet'!D29,'Balance sheet'!D30,'Balance sheet'!D33)/'Balance sheet'!D19 -> 0.79630432 | F18: =SUM('Balance sheet'!E29,'Balance sheet'!E30,'Balance sheet'!E33)/'Balance sheet'!E19 -> 0.77914655 | G18: =SUM('Balance sheet'!F29,'Balance sheet'!F30,'Balance sheet'!F33)/'Balance sheet'!F19 -> 0.93757371 | H18: =SUM('Balance sheet'!G29,'Balance sheet'!G30,'Balance sheet'!G33)/'Balance sheet'!G19 -> 0.88128984 | I18: =SUM('Balance sheet'!H29,'Balance sheet'!H30,'Balance sheet'!H33)/'Balance sheet'!H19 -> 0.54260717 | J18: =SUM('Balance sheet'!I29,'Balance sheet'!I30,'Balance sheet'!I33)/'Balance sheet'!I19 -> 0.5283212 | ... L18: =SUM('Balance sheet'!K29,'Balance sheet'!K30,'Balance sheet'!K33)/'Balance sheet'!K19 -> 0.60994836
A19: Efficiency Ratio
A20: Average inventory | D20: =('Balance sheet'!B16+'Balance sheet'!C16)/2 -> 44805000 | E20: =('Balance sheet'!C16+'Balance sheet'!D16)/2 -> 43757500 | F20: =('Balance sheet'!D16+'Balance sheet'!E16)/2 -> 43414500 | G20: =('Balance sheet'!E16+'Balance sheet'!F16)/2 -> 44026000 | H20: =('Balance sheet'!F16+'Balance sheet'!G16)/2 -> 44352000 | I20: =('Balance sheet'!G16+'Balance sheet'!H16)/2 -> 44692000 | J20: =('Balance sheet'!H16+'Balance sheet'!I16)/2 -> 50730000 | K20: =('Balance sheet'!I16+'Balance sheet'!J16)/2 -> 56543500 | L20: =('Balance sheet'!J16+'Balance sheet'!K16)/2 -> 55734000
A21: Inventory Turnover ratio | D21: =(standardized!B15-standardized!B19)/'financial ratios'!D20 -> 8.0719563 | E21: =(standardized!C15-standardized!C19)/'financial ratios'!E20 -> 8.1692967 | F21: =(standardized!D15-standardized!D19)/'financial ratios'!F20 -> 8.216149 | G21: =(standardized!E15-standardized!E19)/'financial ratios'!G20 -> 8.3771862 | H21: =(standardized!F15-standardized!F19)/'financial ratios'!H20 -> 8.595441 | I21: =(standardized!G15-standardized!G19)/'financial ratios'!I20 -> 8.7390808 | J21: =(standardized!H15-standardized!H19)/'financial ratios'!J20 -> 8.2081017 | K21: =(standardized!I15-standardized!I19)/'financial ratios'!K20 -> 7.498793 | L21: =(standardized!J15-standardized!J19)/'financial ratios'!L20 -> 8.223221
A22: Average fixed assets | D22: =('Balance sheet'!B22+'Balance sheet'!C22)/2 -> 112225500 | E22: =('Balance sheet'!C22+'Balance sheet'!D22)/2 -> 108940500 | F22: =('Balance sheet'!D22+'Balance sheet'!E22)/2 -> 107692500 | G22: =('Balance sheet'!E22+'Balance sheet'!F22)/2 -> 105996000 | H22: =('Balance sheet'!F22+'Balance sheet'!G22)/2 -> 104762500 | I22: =('Balance sheet'!G22+'Balance sheet'!H22)/2 -> 98704500 | J22: =('Balance sheet'!H22+'Balance sheet'!I22)/2 -> 93358000 | K22: =('Balance sheet'!I22+'Balance sheet'!J22)/2 -> 97637500 | L22: =('Balance sheet'!J22+'Balance sheet'!K22)/2 -> 105785000
A23: Fixed Assets Turnover | D23: =standardized!B15/'financial ratios'!D22 -> 4.2969646 | E23: =standardized!C15/'financial ratios'!E22 -> 4.3933523 | F23: =standardized!D15/'financial ratios'!F22 -> 4.4693642 | G23: =standardized!E15/'financial ratios'!G22 -> 4.6771671 | H23: =standardized!F15/'financial ratios'!H22 -> 4.8712946 | I23: =standardized!G15/'financial ratios'!I22 -> 5.2675005 | J23: =standardized!H15/'financial ratios'!J22 -> 5.9473532 | K23: =standardized!I15/'financial ratios'!K22 -> 5.8149994 | L23: =standardized!J15/'financial ratios'!L22 -> 5.7274755
A24: Average total assets | D24: =('Balance sheet'!B25+'Balance sheet'!C25)/2 -> 201643500 | E24: =('Balance sheet'!C25+'Balance sheet'!D25)/2 -> 199203000 | F24: =('Balance sheet'!D25+'Balance sheet'!E25)/2 -> 201673500 | G24: =('Balance sheet'!E25+'Balance sheet'!F25)/2 -> 211908500 | H24: =('Balance sheet'!F25+'Balance sheet'!G25)/2 -> 227895000 | I24: =('Balance sheet'!G25+'Balance sheet'!H25)/2 -> 244495500 | J24: =('Balance sheet'!H25+'Balance sheet'!I25)/2 -> 248678000 | K24: =('Balance sheet'!I25+'Balance sheet'!J25)/2 -> 244028500 | L24: =('Balance sheet'!J25+'Balance sheet'!K25)/2 -> 247798000
A25: Total Assets Turnover | D25: =standardized!B15/'financial ratios'!D24 -> 2.3914929 | E25: =standardized!C15/'financial ratios'!E24 -> 2.4026445 | F25: =standardized!D15/'financial ratios'!F24 -> 2.386615 | G25: =standardized!E15/'financial ratios'!G24 -> 2.339505 | H25: =standardized!F15/'financial ratios'!H24 -> 2.2393164 | I25: =standardized!G15/'financial ratios'!I24 -> 2.1265258 | J25: =standardized!H15/'financial ratios'!J24 -> 2.2327387 | K25: =standardized!I15/'financial ratios'!K24 -> 2.3266217 | L25: =standardized!J15/'financial ratios'!L24 -> 2.4450601 | M25: =AVERAGE(D25:L25) -> 2.3211689
A26: Average Collection Period
A27: Average Recivables | D27: =('Balance sheet'!B15+'Balance sheet'!C15)/2 -> 6201000 | E27: =('Balance sheet'!C15+'Balance sheet'!D15)/2 -> 5729500 | F27: =('Balance sheet'!D15+'Balance sheet'!E15)/2 -> 5724500 | G27: =('Balance sheet'!E15+'Balance sheet'!F15)/2 -> 5948500 | H27: =('Balance sheet'!F15+'Balance sheet'!G15)/2 -> 6283500 | I27: =('Balance sheet'!G15+'Balance sheet'!H15)/2 -> 6400000 | J27: =('Balance sheet'!H15+'Balance sheet'!I15)/2 -> 7398000 | K27: =('Balance sheet'!I15+'Balance sheet'!J15)/2 -> 8106500 | L27: =('Balance sheet'!J15+'Balance sheet'!K15)/2 -> 8364500
A28: Receivables Turnover | D28: =standardized!B15/'financial ratios'!D27 -> 77.766328 | E28: =standardized!C15/'financial ratios'!E27 -> 83.535038 | F28: =standardized!D15/'financial ratios'!F27 -> 84.080182 | G28: =standardized!E15/'financial ratios'!G27 -> 83.342187 | H28: =standardized!F15/'financial ratios'!H27 -> 81.217315 | I28: =standardized!G15/'financial ratios'!I27 -> 81.238438 | J28: =standardized!H15/'financial ratios'!J27 -> 75.051771 | K28: =standardized!I15/'financial ratios'!K27 -> 70.037871 | L28: =standardized!J15/'financial ratios'!L27 -> 72.434814 | N28: 365
A29: Average Collection period | D29: =$N$28/D28 -> 4.6935481 | E29: =$N$28/E28 -> 4.369424 | F29: =$N$28/F28 -> 4.3410943 | G29: =$N$28/G28 -> 4.3795347 | H29: =$N$28/H28 -> 4.4941156 | I29: =$N$28/I28 -> 4.4929471 | J29: =$N$28/J28 -> 4.8633096 | K29: =$N$28/K28 -> 5.2114662 | L29: =$N$28/L28 -> 5.0390134
A32: Gross Fa Turn | C32: ='Balance sheet'!B20/standardized!B17 -> 0.36527259 | D32: ='Balance sheet'!C20/standardized!C17 -> 0.36703379 | E32: ='Balance sheet'!D20/standardized!D17 -> 0.36942164 | F32: ='Balance sheet'!E20/standardized!E17 -> 0.37005414 | G32: ='Balance sheet'!F20/standardized!F17 -> 0.36121344 | H32: ='Balance sheet'!G20/standardized!G17 -> 0.37221641 | I32: ='Balance sheet'!H20/standardized!H17 -> 0.32293781 | J32: ='Balance sheet'!I20/standardized!I17 -> 0.33055029 | ... L32: ='Balance sheet'!K20/standardized!K17 -> 0.33922314 | M32: =AVERAGE(C32:L32) -> 0.35289778
A34: ca to sales | C34: =standardized!B15/'Balance sheet'!B19 -> 7.6208003 | D34: =standardized!C15/'Balance sheet'!C19 -> 7.9452514 | E34: =standardized!D15/'Balance sheet'!D19 -> 8.3433063 | F34: =standardized!E15/'Balance sheet'!E19 -> 8.3092149 | G34: =standardized!F15/'Balance sheet'!F19 -> 8.2448099 | H34: =standardized!G15/'Balance sheet'!G19 -> 8.4122254 | I34: =standardized!H15/'Balance sheet'!H19 -> 6.1646663 | J34: =standardized!I15/'Balance sheet'!I19 -> 7.0033551 | ... L34: =standardized!K15/'Balance sheet'!K19 -> 8.3592882 | M34: =AVERAGE(C34:L34) -> 7.8411391
A35: depreciation | D35: =('Balance sheet'!C21-'Balance sheet'!B21)/(AVERAGE('Balance sheet'!B20:C20)) -> 0.020725096 | E35: =('Balance sheet'!D21-'Balance sheet'!C21)/(AVERAGE('Balance sheet'!C20:D20)) -> 0.028026371 | F35: =('Balance sheet'!E21-'Balance sheet'!D21)/(AVERAGE('Balance sheet'!D20:E20)) -> 0.031246743 | G35: =('Balance sheet'!F21-'Balance sheet'!E21)/(AVERAGE('Balance sheet'!E20:F20)) -> 0.021640914 | H35: =('Balance sheet'!G21-'Balance sheet'!F21)/(AVERAGE('Balance sheet'!F20:G20)) -> 0.04372988 | I35: =('Balance sheet'!H21-'Balance sheet'!G21)/(AVERAGE('Balance sheet'!G20:H20)) -> -0.0077210003 | J35: =('Balance sheet'!I21-'Balance sheet'!H21)/(AVERAGE('Balance sheet'!H20:I20)) -> 0.034815285 | K35: =('Balance sheet'!J21-'Balance sheet'!I21)/(AVERAGE('Balance sheet'!I20:J20)) -> 0.034726087 | L35: =('Balance sheet'!K21-'Balance sheet'!J21)/(AVERAGE('Balance sheet'!J20:K20)) -> 0.035236803 | M35: =AVERAGE(C35:L35) -> 0.026936242
A37: Operation Ratio
A38: COGS/SALES | C38: =standardized!B18/standardized!B17 -> 0.7517456 | D38: =standardized!C18/standardized!C17 -> 0.74872752 | E38: =standardized!D18/standardized!D17 -> 0.7435194 | F38: =standardized!E18/standardized!E17 -> 0.74628005 | G38: =standardized!F18/standardized!F17 -> 0.74902266 | H38: =standardized!G18/standardized!G17 -> 0.75311472 | I38: =standardized!H18/standardized!H17 -> 0.75170213 | J38: =standardized!I18/standardized!I17 -> 0.74901267 | ... L38: =standardized!K18/standardized!K17 -> 0.75624609 | M38: =AVERAGE(C38:L38) -> 0.75079662
A39: sga/sales | C39: =standardized!B20/standardized!B17 -> 0.19235624 | D39: =standardized!C20/standardized!C17 -> 0.20127559 | E39: =standardized!D20/standardized!D17 -> 0.20962885 | F39: =standardized!E20/standardized!E17 -> 0.21287397 | G39: =standardized!F20/standardized!F17 -> 0.20829308 | H39: =standardized!G20/standardized!G17 -> 0.20763068 | I39: =standardized!H20/standardized!H17 -> 0.20797244 | J39: =standardized!I20/standardized!I17 -> 0.20569389 | ... L39: =standardized!K20/standardized!K17 -> 0.20207676 | M39: =AVERAGE(C39:L39) -> 0.20557882
A40: cash/sales | C40: ='Balance sheet'!B14/standardized!B17 -> 0.018809804 | D40: ='Balance sheet'!C14/standardized!C17 -> 0.018055296 | E40: ='Balance sheet'!D14/standardized!D17 -> 0.014133323 | F40: ='Balance sheet'!E14/standardized!E17 -> 0.013502737 | G40: ='Balance sheet'!F14/standardized!F17 -> 0.015011518 | H40: ='Balance sheet'!G14/standardized!G17 -> 0.018064218 | I40: ='Balance sheet'!H14/standardized!H17 -> 0.03172846 | J40: ='Balance sheet'!I14/standardized!I17 -> 0.025770226 | ... L40: ='Balance sheet'!K14/standardized!K17 -> 0.015223915 | M40: =AVERAGE(C40:L40) -> 0.018440903
A41: recev/reveue | C41: ='Balance sheet'!B15/standardized!B17 -> 0.013956524 | D41: ='Balance sheet'!C15/standardized!C17 -> 0.011664904 | E41: ='Balance sheet'!D15/standardized!D17 -> 0.012009311 | F41: ='Balance sheet'!E15/standardized!E17 -> 0.011220303 | G41: ='Balance sheet'!F15/standardized!F17 -> 0.012214111 | H41: ='Balance sheet'!G15/standardized!G17 -> 0.01199319 | I41: ='Balance sheet'!H15/standardized!H17 -> 0.011653382 | J41: ='Balance sheet'!I15/standardized!I17 -> 0.014456468 | ... L41: ='Balance sheet'!K15/standardized!K17 -> 0.013571456 | M41: =AVERAGE(C41:L41) -> 0.012571714
A42: fA/sales | C42: ='Balance sheet'!B20/standardized!B17 -> 0.36527259 | D42: ='Balance sheet'!C20/standardized!C17 -> 0.36703379 | E42: ='Balance sheet'!D20/standardized!D17 -> 0.36942164 | F42: ='Balance sheet'!E20/standardized!E17 -> 0.37005414 | G42: ='Balance sheet'!F20/standardized!F17 -> 0.36121344 | H42: ='Balance sheet'!G20/standardized!G17 -> 0.37221641 | I42: ='Balance sheet'!H20/standardized!H17 -> 0.32293781 | J42: ='Balance sheet'!I20/standardized!I17 -> 0.33055029 | ... L42: ='Balance sheet'!K20/standardized!K17 -> 0.33922314 | M42: =AVERAGE(C42:L42) -> 0.35289778
A43: other A/ sales | C43: =SUM('Balance sheet'!B23:B24)/standardized!B17 -> 0.053841133 | D43: =SUM('Balance sheet'!C23:C24)/standardized!C17 -> 0.060504428 | E43: =SUM('Balance sheet'!D23:D24)/standardized!D17 -> 0.068795755 | F43: =SUM('Balance sheet'!E23:E24)/standardized!E17 -> 0.07431502 | G43: =SUM('Balance sheet'!F23:F24)/standardized!F17 -> 0.10318912 | H43: =SUM('Balance sheet'!G23:G24)/standardized!G17 -> 0.13260644 | I43: =SUM('Balance sheet'!H23:H24)/standardized!H17 -> 0.12559756 | J43: =SUM('Balance sheet'!I23:I24)/standardized!I17 -> 0.1209507 | ... L43: =SUM('Balance sheet'!K23:K24)/standardized!K17 -> 0.099844937 | M43: =AVERAGE(C43:L43) -> 0.094889293
A44: Ap.Acr exp/sales | C44: ='Balance sheet'!B26/standardized!B17 -> 0.12062778 | D44: ='Balance sheet'!C26/standardized!C17 -> 0.12157509 | E44: ='Balance sheet'!D26/standardized!D17 -> 0.12967998 | F44: ='Balance sheet'!E26/standardized!E17 -> 0.13359236 | G44: ='Balance sheet'!F26/standardized!F17 -> 0.13163752 | H44: ='Balance sheet'!G26/standardized!G17 -> 0.12893825 | I44: ='Balance sheet'!H26/standardized!H17 -> 0.12931212 | J44: ='Balance sheet'!I26/standardized!I17 -> 0.13896367 | ... L44: ='Balance sheet'!K26/standardized!K17 -> 0.13250222 | M44: =AVERAGE(C44:L44) -> 0.13027827
A45: Tax Rate | C45: =standardized!B27/standardized!B26 -> 0.32198879 | D45: =standardized!C27/standardized!C26 -> 0.30307792 | E45: =standardized!D27/standardized!D26 -> 0.30267844 | F45: =standardized!E27/standardized!E26 -> 0.30417245 | G45: =standardized!F27/standardized!F26 -> 0.37356021 | H45: =standardized!G27/standardized!G26 -> 0.24433287 | I45: =standardized!H27/standardized!H26 -> 0.33349543 | J45: =standardized!I27/standardized!I26 -> 0.25438596 | ... L45: =standardized!K27/standardized!K26 -> 0.25530941 | M45: =AVERAGE(C45:L45) -> 0.30293908

Sheet Compare with another 
B4: ROA WALMART | E4: =standardized!C25/'Balance sheet'!C20 -> -0.013941161 | F4: =standardized!D25/'Balance sheet'!D20 -> -0.012630089 | G4: =standardized!E25/'Balance sheet'!E20 -> -0.028700433 | H4: =standardized!F25/'Balance sheet'!F20 -> -0.056493192 | I4: =standardized!G25/'Balance sheet'!G20 -> -0.0023176159 | J4: =standardized!H25/'Balance sheet'!H20 -> -0.010987368 | K4: =standardized!I25/'Balance sheet'!I20 -> -0.038273013 | L4: =standardized!J25/'Balance sheet'!J20 -> -0.016860207 | M4: =standardized!K25/'Balance sheet'!K20 -> -0.023487781
B5: Roa costco | E5: =E10 -> 0.2637887 | F5: =F10 -> 0.30872307 | G5: =G10 -> 0.27883014 | H5: =H10 -> 0.27890006 | I5: =I10 -> 0.31329737 | J5: =J10 -> 0.28238781 | K5: =K10 -> 0.30759307 | L5: =L10 -> 0.32743165 | M5: =M10 -> 0.35989247
B6: Roa amazon | E6: =D11 -> -0.014642445 | F6: =E11 -> 0.029219983 | G6: =F11 -> 0.093682089 | H6: =G11 -> 0.087618442 | I6: =H11 -> 0.26374633 | J6: =I11 -> 0.24559693 | K6: =J11 -> 0.2940625 | L6: =K11 -> 0.42413302 | M6: =L11 -> -0.03419598
B10: Return On Assets | D10: ='[2]income statement'!B36/'[2]balance sheet'!B30 -> 0.24237428 | E10: ='[2]income statement'!C36/'[2]balance sheet'!C30 -> 0.2637887 | F10: ='[2]income statement'!D36/'[2]balance sheet'!D30 -> 0.30872307 | G10: ='[2]income statement'!E36/'[2]balance sheet'!E30 -> 0.27883014 | H10: ='[2]income statement'!F36/'[2]balance sheet'!F30 -> 0.27890006 | I10: ='[2]income statement'!G36/'[2]balance sheet'!G30 -> 0.31329737 | J10: ='[2]income statement'!H36/'[2]balance sheet'!H30 -> 0.28238781 | K10: ='[2]income statement'!I36/'[2]balance sheet'!I30 -> 0.30759307 | ... M10: ='[2]income statement'!K36/'[2]balance sheet'!K30 -> 0.35989247
B11: Return on Assets | D11: ='[3]income statment '!B37/'[3]balance sheet '!B29 -> -0.014642445 | E11: ='[3]income statment '!C37/'[3]balance sheet '!C29 -> 0.029219983 | F11: ='[3]income statment '!D37/'[3]balance sheet '!D29 -> 0.093682089 | G11: ='[3]income statment '!E37/'[3]balance sheet '!E29 -> 0.087618442 | H11: ='[3]income statment '!F37/'[3]balance sheet '!F29 -> 0.26374633 | I11: ='[3]income statment '!G37/'[3]balance sheet '!G29 -> 0.24559693 | J11: ='[3]income statment '!H37/'[3]balance sheet '!H29 -> 0.2940625 | K11: ='[3]income statment '!I37/'[3]balance sheet '!I29 -> 0.42413302 | L11: ='[3]income statment '!J37/'[3]balance sheet '!J29 -> -0.03419598
B13: ='financial ratios'!C5 -> 01/31/2015 | C13: ='financial ratios'!D5 -> 01/31/2016 | D13: ='financial ratios'!E5 -> 01/31/2017 | E13: ='financial ratios'!F5 -> 01/31/2018 | F13: ='financial ratios'!G5 -> 01/31/2019 | G13: ='financial ratios'!H5 -> 01/31/2020 | H13: ='financial ratios'!I5 -> 01/31/2021 | I13: ='financial ratios'!J5 -> 01/31/2022 | J13: ='financial ratios'!K5 -> 01/31/2023 | K13: 45322
A14: Debt to equity costco | B14: ='[2]financial ratio'!C17 -> 1.6842234 | C14: ='[2]financial ratio'!D17 -> 2.1496656 | D14: ='[2]financial ratio'!E17 -> 1.7455087 | E14: ='[2]financial ratio'!F17 -> 2.3723325 | F14: ='[2]financial ratio'!G17 -> 2.190093 | G14: ='[2]financial ratio'!H17 -> 1.9784163 | H14: ='[2]financial ratio'!I17 -> 2.0385036 | I14: ='[2]financial ratio'!J17 -> 2.3744022 | J14: ='[2]financial ratio'!K17 -> 2.1085166
